Workbook

Sheet M1
A1: ALKAMO — M1 (arabe) 20 THEMES
A3: N° | B3: THÈME | C3: MOTS
A4: 1 | B4: الطبيعة والتضاريس | C4: =M1_mots!A2 -> 452
A5: 2 | B5: البحر والمحيط | C5: =M1_mots!B2 -> 385
A6: 3 | B6: الطقس والمناخ | C6: =M1_mots!C2 -> 331
A7: 4 | B7: الحيوانات | C7: =M1_mots!D2 -> 260
A8: 5 | B8: التقاليد والعادات | C8: =M1_mots!E2 -> 242
A9: 6 | B9: الصيد وصيد السمك | C9: =M1_mots!F2 -> 325
A10: 7 | B10: الملابس واللباس | C10: =M1_mots!G2 -> 428
A11: 8 | B11: النباتات والأشجار | C11: =M1_mots!H2 -> 347
A12: 9 | B12: الطاقة والموارد الطبيعية | C12: =M1_mots!I2 -> 429
A13: 10 | B13: الطبخ والأطباق | C13: =M1_mots!J2 -> 302
A14: 11 | B14: الموسيقى وآلاتها | C14: =M1_mots!K2 -> 261
A15: 12 | B15: السياحة والسفر | C15: =M1_mots!L2 -> 307
A16: 13 | B16: المدرسة والدراسة | C16: =M1_mots!M2 -> 334
A17: 14 | B17: جسم الإنسان | C17: =M1_mots!N2 -> 168
A18: 15 | B18: الدين والعبادة | C18: =M1_mots!O2 -> 326
A19: 16 | B19: الصحة والتطبيب | C19: =M1_mots!P2 -> 324
A20: 17 | B20: الحرف اليدوية | C20: =M1_mots!Q2 -> 288
A21: 18 | B21: الحيوانات الأليفة | C21: =M1_mots!R2 -> 213
A22: 19 | B22: الأخلاق والصفات | C22: =M1_mots!S2 -> 242
A23: 20 | B23: الحواس والإدراك | C23: =M1_mots!T2 -> 454
A24: TOTAL | C24: =SUM(C4:C23) -> 6418

Sheet M1_mots
A1: الطبيعة والتضاريس | B1: البحر والمحيط | C1: الطقس والمناخ | D1: الحيوانات | E1: التقاليد والعادات | F1: الصيد وصيد السمك | G1: الملابس واللباس | H1: النباتات والأشجار | I1: الطاقة والموارد الطبيعية | J1: الطبخ والأطباق | K1: الموسيقى وآلاتها | L1: السياحة والسفر | M1: المدرسة والدراسة | N1: جسم الإنسان | O1: الدين والعبادة | P1: الصحة والتطبيب | Q1: الحرف اليدوية | R1: الحيوانات الأليفة | S1: الأخلاق والصفات | T1: الحواس والإدراك
A2: =COUNTA(A3:A5000) -> 452 | B2: =COUNTA(B3:B5000) -> 385 | C2: =COUNTA(C3:C5000) -> 331 | D2: =COUNTA(D3:D5000) -> 260 | E2: =COUNTA(E3:E5000) -> 242 | F2: =COUNTA(F3:F5000) -> 325 | G2: =COUNTA(G3:G5000) -> 428 | H2: =COUNTA(H3:H5000) -> 347 | ... T2: =COUNTA(T3:T5000) -> 454
A3: حدائق | B3: سباحة | C3: استوائي | D3: بحر | E3: أجداد | F3: قرن | G3: خياطة | H3: آبنوس | I3: إشعاعي | J3: احتفل | K3: طبول | L3: آثار | M3: أب | N3: جسم | O3: أصنام | P3: حيوي | Q3: حرفي | R3: كلب | S3: ابتكار | T3: إبرة
A4: حيوي | B4: جزر | C4: جفاف | D4: براري | E4: احترام | F4: بحري | G4: داخلي | H4: أجمة | I4: حرارية | J4: أحشاء | K4: أجواء | L4: أثر | M4: ابتدائي | N4: فخذ | O4: مقدسة | P4: عملية | Q4: فخاري | R4: قطة | S4: إبداع | T4: اتجاه
A5: اتساع | B5: سفينة | C5: جوية | D5: حيواني | E5: احتشام | F5: بري | G5: رياضي | H5: أحاط | I5: حفري | J5: أخطبوط | K5: إذاعة | L5: أجنبي | M5: ابتدائية | N5: دموي | O5: أب | P5: فيروس | Q5: مصمم | R5: أرنب | S5: اتفاق | T5: أتى
A6: احترام | B6: صيد | C6: طقس | D6: طنان | E6: احتفال | F6: حيتان | G6: منزلي | H6: أحراش | I6: زيت | J6: أدوات | K6: أذن | L6: إدارة | M6: ابتكر | N6: فقري | O6: ابتهال | P6: مضاد | Q6: إبداع | R6: طائر | S6: اجتماعي | T6: إثارة
A7: أحراش | B7: إبحار | C7: هواء | D7: وحشي | E7: أدب | F7: سمك | G7: إبر | H7: أخضر | I7: شمسية | J7: أرز | K7: ارتجال | L7: أدغال | M7: أبجدية | N7: قدم | O7: اجتهاد | P7: إبرة | Q7: إبرة | R7: سلحفاة | S7: اجتهاد | T7: أثر
A8: إحساس | B8: اتجاه | C8: باردة | D8: ابن | E8: إرث | F8: شم | G8: إبرة | H8: إدارة | I8: طاقة | J8: استقبال | K8: ارتفاع | L8: أرجوحة | M8: إبداع | N8: لوح | O8: أجر | P8: أبهر | Q8: إتقان | R8: همستر | S8: احترام | T8: أثّر
A9: إحيائية | B9: اتصال | C9: جوي | D9: أحفورة | E9: أرجوحة | F9: نشاب | G9: إبزيم | H9: أدغال | I9: فحم | J9: أعشاب | K9: أرغن | L9: أرخبيل | M9: اتجاه | N9: إبط | O9: إجماع | P9: أثر | Q9: أخصائي | R9: حصان | S9: احتقار | T9: أحس
A10: أخاديد | B10: أخطبوط | C10: داكن | D10: أدغال | E10: أرز | F10: أثر | G10: اختيار | H10: ارتفاع | I10: ماء | J10: أفوكادو | K10: أرغول | L10: ازدهار | M10: إجازة | N10: إبهام | O10: احترام | P10: احمرار | Q10: أداة | R10: خروف | S10: احتمال | T10: إحساس
A11: أخلاقي | B11: أرخبيل | C11: رمل | D11: أرانب | E11: أرض | F11: احتجاز | G11: أخضر | H11: أرز | I11: متجددة | J11: أكل | K11: استرخاء | L11: استراح | M11: اجتماع | N11: إحساس | O11: احتفل | P11: أحياء | Q11: أدوات | R11: ماعز | S11: اختراع | T11: أخذ
A12: أدغال | B12: استحم | C12: ريح | D12: أرنب | E12: إزار | F12: اختباء | G12: أدغال | H12: أرض | I12: مشعة | J12: أناناس | K12: استماع | L12: استراحة | M12: اجتهاد | N12: أذن | O12: إحسان | P12: أذن | Q12: إزميل | R12: بقرة | S12: اختلاف | T12: أخلاق
A13: ارتفاع | B13: استغاثة | C13: عاصفة | D13: أروية | E13: استقبال | F13: اختبار | G13: أربطة | H13: إزالة | I13: مفاعل | J13: أنشوجة | K13: استمع | L13: استرخاء | M13: احترام | N13: أربطة | O13: اختيار | P13: أرشيف | Q13: إسكافي | R13: حمار | S13: اختيار | T13: أخلاقي
A14: أرجوحة | B14: أسر | C14: فجر | D14: أسد | E14: أسطورة | F14: أخطبوط | G14: ارتداء | H14: أزاليا | I14: نفط | J14: باذنجان | K14: استوديو | L14: استفاد | M14: أخبر | N14: أسنان | O14: إخلاص | P14: أرضع | Q14: أصالة | R14: دجاجة | S14: إخلاص | T14: إدراك
... A170: رأس | B170: سباح | C170: زراعي | D170: فخ | E170: قربى | F170: شعاب | G170: خطم | H170: ساج | I170: حرارة | J170: طماطم | K170: فرقة | L170: ضباب | M170: طفل | N170: يقظة | O170: صبر | P170: طبي | Q170: عدة | R170: ظهر | S170: فخر | T170: خطة
A171: ربوة | B171: سحاب | C171: زوبعة | D171: فراشة | E171: قرفة | F171: شعر | G171: خفاش | H171: سافانا | I171: حراري | J171: طهوي | K171: فلكلوري | L171: طائرة | M171: عادي | O171: صدقة | P171: طبيب | Q171: عصا | R171: متماسك | S171: فرح | T171: خفي
A172: رسام | B172: سد | C172: سابقاً | D172: فرس | E172: قرية | F172: شغف | G172: خفق | H172: ساق | I172: حرق | J172: طهي | K172: فلوت | L172: طبي | M172: عاقب | O172: صريح | P172: طبيعي | Q172: عطر | R172: متناقض | S172: فشل | T172: خفيف
A173: رسوبي | B173: سرطان | C173: ساحل | D173: فرو | E173: قطن | F173: شفاء | G173: خفيف | H173: سبانخ | I173: حركة | J173: عجن | K173: فن | L173: طبيعة | M173: عالم | O173: صلاة | P173: طفيلي | Q173: علمي | R173: مثقف | S173: فضول | T173: خلود
A174: رطب | B174: سرعة | C174: ساعة | D174: فريسة | E174: قفطان | F174: شمس | G174: خلد | H174: سرخس | I174: حركي | J174: عدس | K174: فنان | L174: طريق | M174: عائلة | O174: صليب | P174: طهر | Q174: عمدة | R174: مجرد | S174: فضيلة | T174: خيال
A175: ركام | B175: سطح | C175: سائل | D175: فطام | E175: قلادة | F175: صاد | G175: خلع | H175: سرو | I175: حريق | J175: عسل | K175: قاد | L175: طعام | M175: عرض | O175: صوفي | P175: طوارئ | Q175: عنبر | R175: مجنون | S175: فكر | T175: خير
A176: رمال | B176: سعة | C176: سحابة | D176: فقمة | E176: قهوة | F176: صبر | G176: خليج | H176: سفرجل | I176: حزمة | J176: عشاء | K176: قاعة | L176: عابر | M176: عرف | O176: صوم | P176: عافية | Q176: غرز | R176: مذهب | S176: فكرة | T176: دار
A177: رمل | B177: سقي | C177: سحب | D177: فك | E177: قول | F177: صحراء | G177: خندق | H177: سقي | I177: حفر | J177: عشب | K177: قائد | L177: عاد | M177: عطلة | O177: صيام | P177: عالج | Q177: غرزة | R177: مراجعة | S177: فهم | T177: دال
A178: رملي | B178: سلح | C178: سرعة | D178: فلامنغو | E178: كحل | F178: صدر | G178: خوذة | H178: سكر | I178: حفظ | J178: عصير | K178: قبائلي | L178: عام | M178: عقاب | O178: طاعة | P178: عام | Q178: غزل | R178: مربك | S178: فوضى | T178: دقة
A179: رملية | B179: سلحفاة | C179: سطح | D179: فهد | E179: كرامة | F179: صف | G179: خياط | H179: سماد | I179: حقل | J179: عنب | K179: قداس | L179: عبارة | M179: علامة | O179: طاهر | P179: عامة | Q179: غطاء | R179: مشكلة | S179: قاس | T179: دقيق
A180: رواسب | B180: سلسلة | C180: سقوط | D180: فيل | E180: كرم | F180: صفارة | G180: خياطةٌ | H180: سنبلة | I180: حكمة | J180: غاسباتشو | K180: قرص | L180: عبور | M180: علم | O180: طائفة | P180: عدوى | Q180: فخار | R180: مشورة | S180: قبول | T180: دل
A181: روح | B181: سلطعون | C181: سكون | D181: قارت | E181: كسكس | F181: صقارة | G181: خيط | H181: سنجاب | I181: حماس | J181: غداء | K181: قرع | L181: عشاء | M181: علمي | O181: طرد | P181: عرض | Q181: فرن | R181: مطلق | S181: قدرة | T181: دلالة
A182: روحانية | B182: سلم | C182: سنة | D182: قارض | E182: كعك | F182: صقر | G182: خيطان | H182: سنط | I182: حمل | J182: غذاء | K182: قرعية | L182: عطلة | M182: علوم | O182: طقس | P182: عصب | Q182: فضة | R182: معرفة | S182: قراءة | T182: دلالي
... A215: شخصية | B215: طائرة | C215: ضوء | D215: ماعز | E215: منهاج | F215: غوريلا | G215: ساق | H215: عائلة | I215: روح | J215: كافيار | K215: مسيرة | L215: كثيب | M215: قلم | O215: فجر | P215: فعال | Q215: متدرب | R215: يقين | S215: مقارنة | T215: سريع
A216: شديد | B216: طحلب | C216: طبقة | D216: مانجو | E216: مهر | F216: فأر | G216: سترات | H216: عرعر | I216: ريح | J216: كاكاو | K216: مشغل | L216: كوخ | M216: قواعد | O216: فدية | P216: فم | Q216: مترجم | S216: مكروه | T216: سلبي
A217: شرط | B217: طراد | C217: طبقي | D217: متجعد | E217: مهرجان | F217: فتيلة | G217: سترة | H217: عرق | I217: ريحي | J217: كبد | K217: مطرب | L217: لافتة | M217: قيادة | O217: فردوس | P217: فيتامين | Q217: محاسب | S217: ملل | T217: سلسلة
A218: شركة | B218: طرف | C218: طوارئ | D218: متوحش | E218: موروث | F218: فخ | G218: سحاب | H218: عشب | I218: زاد | J218: كثيف | K218: معجب | L218: لغة | M218: قيّم | O218: فرض | P218: قاعة | Q218: محامي | S218: مناقشة | T218: سماع
A219: شعاب | B219: طريق | C219: طور | D219: محار | E219: موسم | F219: فرو | G219: سحر | H219: عصارة | I219: زراعي | J219: كراميل | K219: معزوفة | L219: ليلة | M219: كتاب | O219: فضيلة | P219: قافلة | Q219: محرك | S219: منطق | T219: سمع
A220: شعر | B220: طعم | C220: طول | D220: محمي | E220: موكب | F220: فريسة | G220: سراويل | H220: عطري | I220: زلزال | J220: كرز | K220: معلم | L220: ليلي | M220: كتابة | O220: فطر | P220: قرص | Q220: محفظة | S220: مهارة | T220: سمعي
A221: شق | B221: طفو | C221: طين | D221: محمية | E221: مولد | F221: فضة | G221: سروال | H221: عقدة | I221: زينون | J221: كرفس | K221: مغن | L221: مأدبة | M221: كتب | O221: فطرة | P221: قرنية | Q221: مخرج | S221: موقف | T221: سياق
A222: شلال | B222: طمي | C222: ظاهرة | D222: محيط | E222: ميراث | F222: فقمة | G222: سعر | H222: عقلة | I222: ساكن | J222: كركم | K222: مغني | L222: مبيت | M222: كتيب | O222: فقه | P222: قصبة | Q222: مخرز | S222: موهبة | T222: شامل
A223: شمس | B223: طوف | C223: ظرف | D223: مخلب | E223: ميلاد | F223: فك | G223: سلسلة | H223: عمود | I223: سائل | J223: كركند | K223: مغنية | L223: متجر | M223: كرة | O223: فقيه | P223: قطرات | Q223: مخرطة | S223: نبل | T223: شائع
A224: شوّه | B224: طيار | C224: ظهر | D224: مربي | E224: ناي | F224: فهد | G224: سميك | H224: عناب | I224: سرعة | J224: كريم | K224: مقام | L224: متجول | M224: كرتون | O224: فكرة | P224: قلب | Q224: مدبغة | S224: نجاح | T224: شبكية
A225: صاعد | B225: طيران | C225: عاصف | D225: مرعى | E225: نجاح | F225: فيل | G225: سنارة | H225: عنب | I225: سعة | J225: كزبرة | K225: مقدمة | L225: متحرك | M225: كرر | O225: قارئ | P225: قلبي | Q225: مدقق | S225: نزاهة | T225: شخصية
A226: صبار | B226: عامل | C226: عجلة | D226: مرموط | E226: نحاس | F226: قارب | G226: شال | H226: غابة | I226: سعرة | J226: كستناء | K226: مقطع | L226: متحف | M226: كسل | O226: قاض | P226: قلبية | Q226: مدير | S226: نسيان | T226: شدة
A227: صحراء | B227: عبارة | C227: عصر | D227: مروض | E227: نسب | F227: قاع | G227: شتاء | H227: غرس | I227: سكن | J227: كسكس | K227: مقطوعة | L227: مترو | M227: كسول | O227: قاعدة | P227: قلق | Q227: مربي | S227: نشاط | T227: شذى
...

Sheet M2
A1: ALKAMO — M2 (arabe) 20 THEMES
A3: N° | B3: THÈME | C3: MOTS
A4: 1 | B4: الأسرة والعائلة | C4: =M2_mots!A2 -> 273
A5: 2 | B5: العلاقات الإنسانية | C5: =M2_mots!B2 -> 308
A6: 3 | B6: المنزل ومرافقه | C6: =M2_mots!C2 -> 414
A7: 4 | B7: فواكه وخضر | C7: =M2_mots!D2 -> 327
A8: 5 | B8: الضيافة والكرم | C8: =M2_mots!E2 -> 135
A9: 6 | B9: الفيزياء والكيمياء | C9: =M2_mots!F2 -> 402
A10: 7 | B10: الخياطة والحياكة | C10: =M2_mots!G2 -> 358
A11: 8 | B11: العمل والمهنة | C11: =M2_mots!H2 -> 313
A12: 9 | B12: المدينة والعمران | C12: =M2_mots!I2 -> 250
A13: 10 | B13: المباني والمنشآت | C13: =M2_mots!J2 -> 231
A14: 11 | B14: النقل | C14: =M2_mots!K2 -> 244
A15: 12 | B15: الطرق والملاحة | C15: =M2_mots!L2 -> 273
A16: 13 | B16: التعليم والمدرسة | C16: =M2_mots!M2 -> 385
A17: 14 | B17: الحاسوب والإنترنت | C17: =M2_mots!N2 -> 105
A18: 15 | B18: التجارة | C18: =M2_mots!O2 -> 281
A19: 16 | B19: المؤسسات | C19: =M2_mots!P2 -> 296
A20: 17 | B20: اللغة والألفاظ | C20: =M2_mots!Q2 -> 294
A21: 18 | B21: الحساب والأرقام | C21: =M2_mots!R2 -> 250
A22: 19 | B22: الأدوات والمهن | C22: =M2_mots!S2 -> 271
A23: 20 | B23: الزمن والأوقات | C23: =M2_mots!T2 -> 333
A24: TOTAL | C24: =SUM(C4:C23) -> 5743

Sheet M2_mots
A1: الأسرة والعائلة | B1: العلاقات الإنسانية | C1: المنزل ومرافقه | D1: فواكه وخضر | E1: الضيافة والكرم | F1: الفيزياء والكيمياء | G1: الخياطة والحياكة | H1: العمل والمهنة | I1: المدينة والعمران | J1: المباني والمنشآت | K1: النقل | L1: الطرق والملاحة | M1: التعليم والمدرسة | N1: الحاسوب والإنترنت | O1: التجارة | P1: المؤسسات | Q1: اللغة والألفاظ | R1: الحساب والأرقام | S1: الأدوات والمهن | T1: الزمن والأوقات
A2: =COUNTA(A3:A5000) -> 273 | B2: =COUNTA(B3:B5000) -> 308 | C2: =COUNTA(C3:C5000) -> 414 | D2: =COUNTA(D3:D5000) -> 327 | E2: =COUNTA(E3:E5000) -> 135 | F2: =COUNTA(F3:F5000) -> 402 | G2: =COUNTA(G3:G5000) -> 358 | H2: =COUNTA(H3:H5000) -> 313 | ... T2: =COUNTA(T3:T5000) -> 333
A3: أب | B3: أب | C3: طبخ | D3: نيئة | E3: ابتسامة | F3: غليان | G3: خياطة | H3: إجازة | I3: إبداع | J3: آجر | K3: قيادة | L3: أبحر | M3: دراسي | N3: إلكتروني | O3: اتساع | P3: جامعة | Q3: عامية | R3: اثنان | S3: إبرة | T3: أبد
A4: ابن | B4: أبوي | C4: كهربائية | D4: بري | E4: إبريق | F4: كهربائي | G4: ابتكار | H4: اجتماع | I4: أثاث | J4: إدارة | K4: مروري | L4: اتجاه | M4: درجات | N4: اتصال | O4: اتفاق | P4: اتحاد | Q4: فاعل | R4: إجمالي | S4: أجر | T4: أبدا
A5: ابنة | B5: اتصال | C5: إبرة | D5: فلفل | E5: احترام | F5: موجي | G5: إبداع | H5: أجر | I5: إدارة | J5: ارتفاع | K5: ميناء | L5: اتصال | M5: أب | N5: أتمتة | O5: أجرة | P5: اتفاق | Q5: لغوي | R5: آحاد | S5: إحصائي | T5: أبدي
A6: أبوة | B6: اتفاق | C6: إبريق | D6: فواكه | E6: إحسان | F6: إبهام | G6: إبر | H6: اختصاص | I6: إدارية | J6: أرخبيل | K6: ابتكر | L6: إحداثيات | M6: ابتدائي | N6: اختبار | O6: أجل | P6: اتفاقية | Q6: مجهول | R6: احتمال | S6: اختصاص | T6: أبراج
A7: أبوي | B7: اجتماع | C7: آبنوس | D7: مجففة | E7: أدب | F7: اتجاه | G7: إبرة | H7: إدارة | I7: أرض | J7: أردواز | K7: إبرة | L7: أرخبيل | M7: ابتكر | N7: اختراق | O7: آجل | P7: اجتماعية | Q7: ابتلاع | R7: إحداثيات | S7: أداة | T7: أبريل
A8: اجتماع | B8: أحب | C8: أثاث | D8: نباتية | E8: أرز | F8: أثر | G8: اتجاه | H8: أرشيف | I8: أزقة | J8: أرضية | K8: إبلاغ | L8: إرشاد | M8: أبجدية | N8: اشتراك | O8: احتكار | P8: إحصاء | Q8: أبجدية | R8: إحصاء | S8: إزميل | T8: اتجاه
A9: أحب | B9: احترام | C9: أثّث | D9: أبيض | E9: أريكة | F9: احتراق | G9: أثواب | H9: استثمار | I9: استيطان | J9: أساس | K9: اتجاه | L9: استغاثة | M9: إبداع | N9: إشعار | O9: إدارة | P9: اختصاص | Q9: أبكم | R9: اختبار | S9: أستاذ | T9: أثري
A10: احترام | B10: أخ | C10: أثر | D10: أترج | E10: استراحة | F10: احتكاك | G10: أحذية | H10: استقالة | I10: إسفلت | J10: أسلوب | K10: اتصال | L10: استكشاف | M10: اتجاه | N10: إصدار | O10: ادخار | P10: إدارة | Q10: اتساع | R10: آخر | S10: إسكافي | T10: إجازة
A11: أخ | B11: اختلاف | C11: أجّر | D11: أحمر | E11: استقبال | F11: أحفورة | G11: أحزمة | H11: استيراد | I11: أسقفية | J11: إسمنت | K11: أثر | L11: أسر | M11: إجازة | N11: إصلاح | O11: ارتفاع | P11: إداري | Q11: إثبات | R11: أدنى | S11: اكتسب | T11: أجل
A12: أخت | B12: إخلاص | C12: أحرق | D12: إخصاب | E12: أصدقاء | F12: أحياء | G12: أحمر | H12: إعلان | I12: إسكان | J12: إصلاح | K12: إرسال | L12: أسطرلاب | M12: اجتماع | N12: إغلاق | O12: أزمة | P12: إذاعة | Q12: أجنبي | R12: أربعة | S12: آلة | T12: أجّل
A13: أخوة | B13: أخوة | C13: أداة | D13: أخضر | E13: اعتزاز | F13: اختراع | G13: اختيار | H13: اقتصاد | I13: إسمنت | J13: أصلي | K13: ازدحام | L13: أسطول | M13: اجتهاد | N13: إلغاء | O13: استثمار | P13: إرث | Q13: أخرس | R13: ارتفاع | S13: إنتاج | T13: احتفال
A14: إرث | B14: ارتباط | C14: أرض | D14: أرض | E14: إعداد | F14: اختزال | G14: أربطة | H14: إنتاج | I14: إشارة | J14: إطار | K14: أزعج | L14: إشارات | M14: احترام | N14: أمن | O14: استثمر | P14: أرشيف | Q14: أداة | R14: أس | S14: باحث | T14: أحد
... A107: دلل | B107: حوار | C107: جوهرة | D107: حلو | E107: مجاملة | F107: جاذبية | G107: خرزة | H107: وكيل | I107: شاطئي | J107: شبكة | K107: رحلة | L107: زاوية | M107: جواب | N107: وسم | O107: حوالة | P107: خيرية | Q107: حروف | R107: سهم | S107: عاطل | T107: حرارة
A108: دم | B108: حياة | C108: جير | D108: حلوة | E108: مجلس | F108: جذب | G108: خصر | H108: مساعد | I108: شبكة | J108: شجرة | K108: رحيل | L108: زقاق | M108: حاسوب | O108: حول | P108: دار | Q108: حساسية | R108: شريط | S108: عالم | T108: حركة
A109: دور | B109: خاص | C109: حاجز | D109: حلوى | E109: مجمرة | F109: جرعة | G109: خط | H109: شحاذ | I109: شرطة | J109: شرفة | K109: رخصة | L109: زورق | M109: حاشية | O109: خام | P109: دائرة | Q109: حسي | R109: شكل | S109: عامل | T109: حساب
A110: ذاكرة | B110: خبر | C110: حارس | D110: حمص | E110: محشي | F110: جزيء | G110: خفيف | H110: متسلق | I110: شرفة | J110: شريط | K110: رسالة | L110: ساحل | M110: حبر | O110: خباز | P110: دبلوماسي | Q110: حكاية | R110: شهر | S110: عتاد | T110: حقبة
A111: ذرية | B111: خجل | C111: حاسوب | D111: حمضية | E111: مخدة | F111: جسم | G111: خياط | H111: هاوٍ | I111: شريان | J111: شقة | K111: رسم | L111: سباحة | M111: حرر | O111: خدمة | P111: دفاع | Q111: حكمة | R111: شيء | S111: عداء | T111: حقيقي
A112: ذكرى | B112: خصام | C112: حانة | D112: حموضة | E112: مدعو | F112: جسيم | G112: خياطةٌ | H112: محلل | I112: صالة | J112: شكل | K112: رصيف | L112: سحيق | M112: حرف | O112: خزنة | P112: دكتور | Q112: حلاوة | R112: صحيح | S112: عدة | T112: حمل
A113: رابط | B113: خصم | C113: حاوية | D113: خبز | E113: مستضيف | F113: جلد | G113: خيال | H113: مقدم | I113: صالون | J113: شلال | K113: رفع | L113: سد | M113: حرفة | O113: خسارة | P113: دولة | Q113: حلق | R113: صريح | S113: عدسة | T113: حول
A114: ربى | B114: خلاف | C114: حبل | D114: خرشوف | E114: مسك | F114: جمجمة | G114: خيط | H114: مؤرخ | I114: صرح | J114: شمع | K114: ركب | L114: سرعة | M114: حركة | O114: خشب | P114: دولية | Q114: حلو | R114: صفر | S114: عطار | T114: حياة
A115: ربيب | B115: خيانة | C115: حجر | D115: خريف | E115: مشوي | F115: جميل | G115: خيطان | H115: قدرة | I115: صرف | J115: صالة | K115: رنة | L115: سعة | M115: حرم | O115: خصم | P115: دين | Q115: حليمة | R115: صيغة | S115: عمدة | T115: حين
A116: ربيبة | B116: خير | C116: حجز | D116: خس | E116: مصافحة | F116: جهاز | G116: خيوط | H116: حكم | I116: صناعية | J116: صرف | K116: رواية | L116: سفر | M116: حساب | O116: دائرة | P116: دينية | Q116: حموضة | R116: ضرب | S116: فارس | T116: حيوية
A117: رحم | B117: داخل | C117: حديقة | D117: خضار | E117: مضيف | F117: جهد | G117: دانتيل | H117: خازن | I117: صيانة | J117: صندوق | K117: زورق | L117: سفينة | M117: حسب | O117: دائن | P117: ديوان | Q117: حنجرة | R117: ضعف | S117: فأس | T117: خالد
A118: رضاعة | B118: داعب | C118: حرم | D118: خضر | E118: مطبوخ | F118: جول | G118: دبابيس | H118: مساح | I118: ضاحية | J118: صورة | K118: ساحلي | L118: سكة | M118: حصة | O118: دخل | P118: رابطة | Q118: حوار | R118: ضلع | S118: فرشاة | T118: خروج
A119: رضيع | B119: دائرة | C119: حريق | D119: خضروات | E119: معارف | F119: جير | G119: دبس | H119: فنان | I119: ضجيج | J119: صومعة | K119: ساخن | L119: سلح | M119: حصيلة | O119: درهم | P119: راتب | Q119: خاص | R119: طبيعي | S119: فلاح | T119: خريف
... A137: شجرة | B137: رفقة | C137: خشبيات | D137: ريحان | E137: وليمة | F137: دائرة | G137: زبائن | H137: بديل | I137: فرع | J137: غاز | K137: شرح | L137: شمال | M137: داخلي | O137: رقابة | P137: سوق | Q137: روى | R137: فارق | S137: قيّم | T137: ربيع
A138: شرنقة | B138: رفيق | C138: خفيف | D138: زائفة | F138: دخان | G138: زبون | H138: مصارع | I138: فضاء | J138: فرن | K138: شركة | L138: صابورة | M138: دخول | O138: رواج | P138: سياسة | Q138: ريق | R138: فاصلة | S138: كاتب | T138: رذاذ
A139: شعار | B139: زائر | C139: خلاط | D139: زبادي | F139: دراسة | G139: زخارف | H139: رقيب | I139: فن | J139: فضاء | K139: صاروخ | L139: صاري | M139: دراسة | O139: زبائن | P139: شباك | Q139: ساكن | R139: فرد | S139: كاهن | T139: رسمي
A140: شيخوخة | B140: زمالة | C140: خيط | D140: زبدة | F140: درجة | G140: زخرفة | H140: مغني | I140: فناء | J140: فضة | K140: صيف | L140: صدفة | M140: درجة | O140: زبون | P140: شبكة | Q140: سبب | R140: فردي | S140: كماشة | T140: رطب
A141: صالون | B141: زميل | C141: داخل | D141: زبيب | F141: دفع | G141: زر | H141: لحام | I141: فنان | J141: فكرة | K141: ضاحية | L141: صعود | M141: درس | O141: زراعة | P141: شراكة | Q141: سجل | R141: فرصة | S141: كهربائي | T141: رقم
A142: صبر | B142: زواج | C142: داخلي | D142: زراعة | F142: دقيقة | G142: زي | H142: نجار | I142: فندق | J142: فن | K142: طاقم | L142: صندل | M142: درّس | O142: زراعي | P142: شرطة | Q142: سرد | R142: فرق | S142: كيميائي | T142: رمضان
A143: صداقة | B143: زوج | C143: دار | D143: زرع | F143: دم | G143: زين | H143: صياد | I143: فيلا | J143: فناء | K143: طائرة | L143: صندوق | M143: دعم | O143: سجل | P143: شرعية | Q143: سكون | R143: فضاء | S143: لحام | T143: رن
A144: صديق | B144: زوجان | C144: داكن | D144: زعتر | F144: دماغ | G144: زينة | H144: سائق | I144: قاعة | J144: فندق | K144: طراد | L144: ضاعف | M144: دفتر | O144: سحب | P144: شركة | Q144: سمعي | R144: فئة | S144: لوجستي | T144: ريح
A145: صديقة | B145: زوجة | C145: دبوس | D145: زعرور | F145: دوران | G145: ساتان | H145: باحث | I145: قبة | J145: فولاذ | K145: طرد | L145: ضباب | M145: دكتوراه | O145: سعر | P145: شريك | Q145: سؤال | R145: قاس | S145: مبتكر | T145: زامن
A146: صغرى | B146: زوجي | C146: درجة | D146: زعفران | F146: دورق | G146: ساق | H146: كيميائي | I146: قرار | J146: فيلا | K146: طريق | L146: ضفة | M146: دليل | O146: سقوط | P146: شعبي | Q146: سياق | R146: قاسم | S146: مبدع | T146: زائل
A147: صلة | B147: زيارة | C147: دش | D147: زهرة | F147: دينامومتر | G147: ستائر | H147: جراح | I147: قرية | J147: قاعة | K147: طوف | L147: طارد | M147: دمج | O147: سلسلة | P147: شهادة | Q147: شاوية | R147: قاعدة | S147: مبرد | T147: زمان
A148: صهر | B148: سامح | C148: دلو | D148: زيت | F148: ذراع | G148: سترات | H148: عاطل | I148: قصبة | J148: قاعدة | K148: طيار | L148: طاقم | M148: دورة | O148: سلعة | P148: صحي | Q148: شتيمة | R148: قدّر | S148: مبرمج | T148: زمانية
A149: ضحى | B149: سر | C149: دولاب | D149: زيتون | F149: ذري | G149: سترة | H149: منشد | I149: قصر | J149: قبة | K149: عام | L149: طائرة | M149: ديوان | O149: سمسار | P149: صحية | Q149: شدة | R149: قرّب | S149: متدرب | T149: زمن
...

Sheet M3
A1: ALKAMO — M3 (arabe) 20THEMES
A3: N° | B3: THÈME | C3: MOTS
A4: 1 | B4: الطيور | C4: =M3_mots!A2 -> 232
A5: 2 | B5: الفضاء والكون | C5: =M3_mots!B2 -> 264
A6: 3 | B6: التخطيط العمراني | C6: =M3_mots!C2 -> 201
A7: 4 | B7: وقاية وأمن | C7: =M3_mots!D2 -> 186
A8: 5 | B8: الأوزان والمقاييس | C8: =M3_mots!E2 -> 201
A9: 6 | B9: الرياضة والألعاب | C9: =M3_mots!F2 -> 420
A10: 7 | B10: الأدب و الشعر | C10: =M3_mots!G2 -> 333
A11: 8 | B11: علم الأحياء | C11: =M3_mots!H2 -> 165
A12: 9 | B12: التاريخ | C12: =M3_mots!I2 -> 309
A13: 10 | B13: الشخصية والسلوك | C13: =M3_mots!J2 -> 396
A14: 11 | B14: المال والاقتصاد | C14: =M3_mots!K2 -> 272
A15: 12 | B15: الإدارة | C15: =M3_mots!L2 -> 285
A16: 13 | B16: الجبال والصحراء | C16: =M3_mots!M2 -> 382
A17: 14 | B17: الزراعة والفلاحة | C17: =M3_mots!N2 -> 262
A18: 15 | B18: علم الاجتماع | C18: =M3_mots!O2 -> 265
A19: 16 | B19: العلوم التقنية | C19: =M3_mots!P2 -> 124
A20: 17 | B20: التغذية وعلم الحمية | C20: =M3_mots!Q2 -> 123
A21: 18 | B21: الحرب والقتال | C21: =M3_mots!R2 -> 327
A22: 19 | B22: الصوت والضوء | C22: =M3_mots!S2 -> 133
A23: 20 | B23: العدالة والقانون | C23: =M3_mots!T2 -> 388
A24: TOTAL | C24: =SUM(C4:C23) -> 5268

Sheet M3_mots
A1: الطيور | B1: الفضاء والكون | C1: التخطيط العمراني | D1: وقاية وأمن | E1: الأوزان والمقاييس | F1: الرياضة والألعاب | G1: الأدب و الشعر | H1: علم الأحياء | I1: التاريخ | J1: الشخصية والسلوك | K1: المال والاقتصاد | L1: الإدارة | M1: الجبال والصحراء | N1: الزراعة والفلاحة | O1: علم الاجتماع | P1: العلوم التقنية | Q1: التغذية وعلم الحمية | R1: الحرب والقتال | S1: الصوت والضوء | T1: العدالة والقانون
A2: =COUNTA(A3:A5000) -> 232 | B2: =COUNTA(B3:B5000) -> 264 | C2: =COUNTA(C3:C5000) -> 201 | D2: =COUNTA(D3:D5000) -> 186 | E2: =COUNTA(E3:E5000) -> 201 | F2: =COUNTA(F3:F5000) -> 420 | G2: =COUNTA(G3:G5000) -> 333 | H2: =COUNTA(H3:H5000) -> 165 | ... T2: =COUNTA(T3:T5000) -> 388
A3: أبوي | B3: تبانة | C3: إبداع | D3: إسعافات | E3: أثقال | F3: سلة | G3: إبداع | H3: اتزان | I3: اتفاق | J3: ابتكار | K3: صرف | L3: إداري | M3: أبعد | N3: تربة | O3: ميداني | P3: إلكتروني | Q3: غذائية | R3: حربي | S3: أبيض | T3: توقيف
A4: ارتفاع | B4: جاذبية | C4: أثاث | D4: إسفنجة | E4: أثلاث | F4: قدم | G4: أبواب | H4: أحفورة | I4: أثر | J4: إبداع | K4: صعبة | L4: إبراء | M4: اتجاه | N4: حصاد | O4: ابتكار | P4: تشغيل | Q4: نباتي | R4: سلام | S4: أحمر | T4: شرطة
A5: ازدهار | B5: فلكية | C5: إدارة | D5: أسنان | E5: أحجام | F5: ابتكر | G5: أحداث | H5: إخصاب | I5: احتلال | J5: إجابة | K5: إبراء | L5: اتصال | M5: اتساع | N5: بور | O5: إبداع | P5: معلوماتي | Q5: أخصائي | R5: إبادة | S5: أخضر | T5: قضائية
A6: إسطبل | B6: زحل | C6: أرض | D6: إشارة | E6: أداة | F6: اتحاد | G6: إحساس | H6: استقلاب | I6: اختراع | J6: اجتماعي | K6: اتساع | L6: اتفاق | M6: أتون | N6: حشري | O6: اجتماعي | P6: ابتكار | Q6: أرز | R6: اتحاد | S6: إذاعة | T6: ابتزاز
A7: أشقر | B7: شمسية | C7: إسفلت | D7: إصابة | E7: أدوات | F7: اجتماعي | G7: إحيائي | H7: استنساخ | I7: آخر | J7: اجتهاد | K7: اتفاقية | L7: إجازة | M7: أثر | N7: زراعي | O7: احتجاج | P7: اتصال | Q7: استقلاب | R7: اتفاق | S7: أذن | T7: إبراء
A8: أصفر | B8: صاروخ | C8: أسقفية | D8: إصلاح | E8: أذرع | F8: أجواء | G8: أدب | H8: أعصاب | I8: أدب | J8: إحباط | K8: أجر | L8: اجتماع | M8: أخضر | N8: زراعية | O8: احترام | P8: أتمتة | Q8: اعتدال | R8: احتكاك | S8: أزرق | T8: أبرم
A9: افتراس | B9: صناعي | C9: إسمنت | D9: إضاءة | E9: أرباع | F9: احتفال | G9: أدبي | H9: افتراس | I9: أرشيف | J9: احترام | K9: أجرة | L9: إجراء | M9: ارتفاع | N9: زغبي | O9: احتقار | P9: اختراع | Q9: إفراط | R9: احتلال | S9: استماع | T9: أبلغ
A10: إقلاع | B10: فضاء | C10: إشارة | D10: إطفاء | E10: ارتفاع | F10: أحجية | G10: أديب | H10: إفراز | I10: أرض | J10: احتقار | K10: أجل | L10: احتفال | M10: أرض | N10: عضوية | O10: إحصاء | P10: أداة | Q10: إفطار | R10: احتياط | S10: أسود | T10: اتفاق
A11: أقلع | B11: فضائية | C11: إضاءة | D11: آلة | E11: أرطال | F11: أحيا | G11: ارتجال | H11: اكتشاف | I11: ازدهار | J11: أحمق | K11: احتكار | L11: إحصاء | M11: إزهار | N11: نباتية | O11: أخلاق | P11: استشعار | Q11: أكل | R11: أحرق | S11: أصفر | T11: اتهام
A12: ديك | B12: فلكي | C12: إطار | D12: أمان | E12: أزمنة | F12: اختبار | G12: أرجوزة | H12: أكسجين | I12: أزمة | J12: اختيار | K12: احتياطي | L12: أحياء | M12: استقرار | N12: إثمار | O12: إرث | P12: إشارة | Q12: ألياف | R12: اختراق | S12: إضاءة | T12: اتهم
A13: أليف | B13: أثر | C13: إقامة | D13: إنذار | E13: أسابيع | F13: اختراع | G13: استعارة | H13: ألياف | I13: استعمار | J13: إخلاص | K13: إدارة | L13: اختصار | M13: استيطان | N13: أدغال | O13: أرشفة | P13: إصلاح | Q13: امتصاص | R13: إخلاء | S13: امتصاص | T13: إثبات
A14: أملس | B14: إحداثيات | C14: إقليمي | D14: أنف | E14: أسبوع | F14: اخترع | G14: أسطورة | H14: امتصاص | I14: استقلال | J14: إدراك | K14: ادخار | L14: اختيار | M14: أسطرلاب | N14: أرز | O14: ازدراء | P14: اكتشاف | Q14: إنزيم | R14: أرض | S14: انتشار | T14: أثبت
... A125: شرفة | B125: دراسة | C125: قلعة | D125: قناع | E125: قنطار | F125: خادم | G125: ديوان | H125: كربون | I125: راية | J125: حازم | K125: رأسمال | L125: رقابة | M125: داخل | N125: راعي | O125: دولة | P125: واقع | Q125: وزن | R125: درك | S125: نهار | T125: تنفيذ
A126: شعر | B126: درب | C126: قناة | D126: قواعد | E126: قوارير | F126: خبر | G126: راو | H126: كربوهيدرات | I126: رحلة | J126: حب | K126: ربح | L126: رئيس | M126: دائم | N126: رطوبة | O126: دين | P126: وزن | R126: دعم | S126: نور | T126: تهمة
A127: شوك | B127: دفق | C127: قوس | D127: كاشف | E127: قياس | F127: خبرة | G127: راوي | H127: كريات | I127: رحيل | J127: حدسي | K127: رسم | L127: زبائن | M127: دخان | N127: رعي | O127: رأسمالية | R127: دفاع | S127: هاتف | T127: توجيه
A128: صحراء | B128: دليل | C128: كازينو | D128: كسر | E128: كأس | F128: خداع | G128: راوية | H128: كلية | I128: رسالة | J128: حديث | K128: رسوم | L128: زراعي | M128: درب | N128: ركيزة | O128: رأي | R128: دم | S128: هالة | T128: ثقة
A129: صرخة | B129: ذرة | C129: كتلة | D129: كلور | E129: كبير | F129: خدعة | G129: رأي | H129: لحاء | I129: رسم | J129: حذر | K129: رصيد | L129: ساحة | M129: درج | N129: رمان | O129: رحمة | R129: دين | S129: هدوء | T129: جدارة
A130: صغار | B130: رائد | C130: كثافة | D130: كمامة | E130: كتل | F130: خدم | G130: ربع | H130: لقاح | I130: رسول | J130: حزم | K130: رفاهية | L130: سباق | M130: درجات | N130: رمل | O130: رذيلة | R130: ذخيرة | S130: هدير | T130: جرم
A131: صغير | B131: ربع | C131: كثيف | D131: كهرباء | E131: كتلة | F131: خدمة | G131: رثاء | H131: ماء | I131: رق | J131: حزن | K131: رقابة | L131: سجل | M131: دليل | N131: روث | O131: رسمية | R131: رادار | S131: همس | T131: جريمة
A132: صقر | B132: رصد | C132: كنيسة | D132: لحام | E132: كثافة | F132: خسارة | G132: رحيل | H132: مبيض | I132: تنقيب | J132: حساس | K132: رقعة | L132: سفارة | M132: دوار | N132: روضة | O132: رفاق | R132: رامٍ | S132: همهمة | T132: جزاء
A133: صوت | B133: زاوية | C133: كورنيش | D133: لهب | E133: كلفن | F133: خسر | G133: رسالة | H133: مجهر | I133: رمح | J133: حسد | K133: رقمي | L133: سكرتير | M133: دير | N133: ري | O133: رمز | R133: راية | S133: وتر | T133: جلسة
A134: صوف | B134: سحابة | C134: لافتة | D134: لوائح | E134: كميات | F134: خشب | G134: رسائل | H134: مختبر | I134: رواية | J134: حسن | K134: ركود | L134: سلسلة | M134: ذئب | N134: ريف | O134: ريف | R134: رائد | S134: وميض | T134: جناية
A135: صياح | B135: سحر | C135: لائحة | D135: ماء | E135: كمية | F135: خصم | G135: رف | H135: مرض | I135: رئيس | J135: حسود | K135: رهان | L135: سلطة | M135: راحل | N135: زبل | O135: زملاء | R135: رتبة | S135: وهج | T135: جنائي
A136: صياد | B136: سديم | C136: لباقة | D136: مبيد | E136: كوب | F136: خط | G136: رقة | H136: مستضد | I136: زراعة | J136: حقد | K136: رهن | L136: سلّم | M136: راكب | N136: زراعة | O136: زواج | R136: رجل | T136: جنحة
A137: صيد | B137: سراب | C137: ماء | D137: مجاري | E137: كؤوس | F137: خطأ | G137: رمز | H137: مشيمة | I137: زعيم | J137: حكمة | K137: ريادة | L137: سلوك | M137: ربوة | N137: زرع | O137: سكان | R137: رصاص | T137: حادث
A138: طار | B138: سرعة | C138: مأوى | D138: مجرى | E138: كيل | F138: خطة | G138: رمزي | H138: مصاب | I138: زمن | J138: حكيم | K138: زبون | L138: سمح | M138: رحلة | N138: زهرة | O138: سكن | R138: رقيب | T138: حارس
A139: طاووس | B139: سفينة | C139: مبادل | D139: مجمد | E139: كيلة | F139: خطر | G139: رموز | H139: مصل | I139: سابق | J139: حليم | K139: زراعي | L139: شرط | M139: رشيق | N139: زيتون | O139: سلام | R139: رمح | T139: حبس
A140: طائر | B140: سماوي | C140: مبنى | D140: مخاطر | E140: كيلو | F140: خطط | G140: رواة | H140: معدة | I140: ساحل | J140: حماس | K140: سبيكة | L140: شريك | M140: رطب | N140: ساق | O140: سلطة | R140: رهان | T140: حجز
A141: طنان | B141: سمت | C141: مبني | D141: مخبر | E141: كيلوغرام | F141: خطوة | G141: رواية | H141: معدن | I141: سجل | J141: حماية | K141: سعر | L141: شغل | M141: رعد | N141: سقاية | O141: سلمية | R141: رهينة | T141: حدد
A142: طنانة | B142: سنة | C142: متحف | D142: مخرج | E142: كيلومتر | F142: خوذة | G142: روائي | H142: مكتسب | I142: سجن | J142: حنان | K142: سقوط | L142: شكاية | M142: رعوي | N142: سقي | O142: سلوك | R142: زي | T142: حدود
A143: طوقان | B143: شرط | C143: مجال | D143: مخلفات | E143: كيلومترات | F143: دائرة | G143: رومانسي | H143: ملاحظة | I143: سجين | J143: حنكة | K143: سلعة | L143: شكوى | M143: رفع | N143: سلالة | O143: سياسة | R143: سبب | T143: حراسة
A144: طير | B144: شروق | C144: مجمع | D144: مراقبة | E144: لتر | F144: دخول | G144: رويّ | H144: مملكة | I144: سر | J144: حنين | K144: سمسار | L144: شهادة | M144: رق | N144: سماد | O144: سياق | R144: سجن | T144: حرية
A145: طيران | B145: شعار | C145: محطة | D145: مرحاض | E145: لترات | F145: دراج | G145: زحاف | H145: مناعة | I145: سفير | J145: حوار | K145: سمسرة | L145: شيك | M145: ركام | N145: سنبلة | O145: سيطرة | R145: سجين | T145: حزم
A146: طين | B146: شعب | C146: محلي | D146: مرش | E146: لحظات | F146: دراجات | G146: زهد | H146: موت | I146: سقوط | J146: حياء | K146: سنتيم | L146: صادق | M146: ركض | N146: سوق | O146: شباب | R146: سرب | T146: حصانة
A147: عائلة | B147: شمال | C147: محيط | D147: مرشح | E147: لحظة | F147: درب | G147: سبب | H147: موطن | I147: سكان | J147: حيرة | K147: سند | L147: صلاحية | M147: رمل | N147: سياج | O147: شذوذ | R147: سرعة | T147: حصّل
... A167: فراشة | B167: عينة | C167: مقاطعة | D167: ممنوع | E167: معدل | F167: رشاقة | G167: صرف | H167: يود | I167: صانع | J167: ذم | K167: طاقة | L167: فرع | M167: سماء | N167: عدس | O167: ظلم | R167: صادق | T167: درك
A168: فرخ | B168: غاز | C168: مقبرة | D168: مناديل | E168: معدلات | F168: رغبي | G168: صفات | I168: صداقة | J168: راحة | K168: طلب | L168: فقرة | M168: سماكة | N168: عرض | O168: عادات | R168: صاروخ | T168: دستور
A169: فرع | B169: غد | C169: مقعد | D169: منشفة | E169: معيار | F169: رفض | G169: صفة | I169: صغير | J169: رحمة | K169: عامل | L169: فوض | M169: سماوي | N169: عزيق | O169: عادة | R169: صاعق | T169: دعوى
...

Sheet M4
A1: ALKAMO — M4 (arabe) 20THEMES
A3: N° | B3: THÈME | C3: MOTS
A4: 1 | B4: الدين والعبادة | C4: =M4_mots!A2 -> 327
A5: 2 | B5: الحضارات والآثار | C5: =M4_mots!B2 -> 286
A6: 3 | B6: الجغرافيا والبلدان | C6: =M4_mots!C2 -> 86
A7: 4 | B7: علم الاجتماع | C7: =M4_mots!D2 -> 230
A8: 5 | B8: الفلسفة | C8: =M4_mots!E2 -> 228
A9: 6 | B9: المخاطر والكوارث | C9: =M4_mots!F2 -> 375
A10: 7 | B10: الشهرة والنجومية | C10: =M4_mots!G2 -> 358
A11: 8 | B11: الشجاعة والبطولة | C11: =M4_mots!H2 -> 249
A12: 9 | B12: القرية والريف | C12: =M4_mots!I2 -> 280
A13: 10 | B13: الملاحة والقرصنة | C13: =M4_mots!J2 -> 334
A14: 11 | B14: الأعياد والتقاليد | C14: =M4_mots!K2 -> 300
A15: 12 | B15: المهن والوظائف | C15: =M4_mots!L2 -> 202
A16: 13 | B16: المطعم والضيافة | C16: =M4_mots!M2 -> 281
A17: 14 | B17: العيوب والجودة | C17: =M4_mots!N2 -> 445
A18: 15 | B18: علم الزراعة | C18: =M4_mots!O2 -> 137
A19: 16 | B19: البيئة والإيكولوجيا | C19: =M4_mots!P2 -> 332
A20: 17 | B20: الطاقة والموارد | C20: =M4_mots!Q2 -> 429
A21: 18 | B21: المعادن والمواد | C21: =M4_mots!R2 -> 178
A22: 19 | B22: الشرطة والتحقيق الجنائي | C22: =M4_mots!S2 -> 219
A23: 20 | B23: سينما ومسرح | C23: =M4_mots!T2 -> 369
A24: TOTAL | C24: =SUM(C4:C23) -> 5645

Sheet M4_mots
A1: الدين والعبادة | B1: الحضارات والآثار | C1: الجغرافيا والبلدان | D1: علم الاجتماع | E1: الفلسفة | F1: المخاطر والكوارث | G1: الشهرة والنجومية | H1: الشجاعة والبطولة | I1: القرية والريف | J1: الملاحة والقرصنة | K1: الأعياد والتقاليد | L1: المهن والوظائف | M1: المطعم والضيافة | N1: العيوب والجودة | O1: علم الزراعة | P1: البيئة والإيكولوجيا | Q1: الطاقة والموارد | R1: المعادن والمواد | S1: الشرطة والتحقيق الجنائي | T1: سينما ومسرح
A2: =COUNTA(A3:A5000) -> 327 | B2: =COUNTA(B3:B5000) -> 286 | C2: =COUNTA(C3:C5000) -> 86 | D2: =COUNTA(D3:D5000) -> 230 | E2: =COUNTA(E3:E5000) -> 228 | F2: =COUNTA(F3:F5000) -> 375 | G2: =COUNTA(G3:G5000) -> 358 | H2: =COUNTA(H3:H5000) -> 249 | ... T2: =COUNTA(T3:T5000) -> 369
A3: أصنام | B3: إبرة | C3: استوائية | D3: أسرة | E3: أبد | F3: إبادة | G3: شخصية | H3: إباء | I3: إبريق | J3: إبحار | K3: عيد | L3: إحصائي | M3: ابتسامة | N3: ابتذال | O3: تربة | P3: برية | Q3: حفري | R3: إتريوم | S3: ضرر | T3: ابتكار
A4: مقدسة | B4: إبريق | C4: بركان | D4: إنسان | E4: أبدي | F4: ابتكار | G4: ابتكر | H4: إتقان | I4: أجبان | J4: أبحر | K4: احتفال | L4: أستاذ | M4: اجتماع | N4: ابتزاز | O4: حشري | P4: صيد | Q4: زيت | R4: إثمد | S4: معاملة | T4: إبداع
A5: أب | B5: أثر | C5: جزيرة | D5: بيئة | E5: أبيقورية | F5: أتلف | G5: اتجاه | H5: أتون | I5: اجتماع | J5: اتجاه | K5: تقليد | L5: إسكافي | M5: احترام | N5: ابتكار | O5: زراعي | P5: كهرباء | Q5: شمسية | R5: أداميت | S5: مؤامرة | T5: أجواء
A6: ابتهال | B6: أثرى | C6: أرخبيل | D6: تضامن | E6: اختيار | F6: إجرامي | G6: اجتهاد | H6: أثر | I6: احتفال | J6: اتصال | K6: عادة | L6: اكتسب | M6: احتفال | N6: إتاحة | O6: زراعية | P6: نفايات | Q6: طاقة | R6: إريديوم | S6: إبادة | T6: اختيار
A7: اجتهاد | B7: أحرق | C7: أرض | D7: تطور | E7: آخر | F7: إجلاء | G7: أجر | H7: اختبار | I7: أحراش | J7: اتفاق | K7: موسم | L7: باحث | M7: إحسان | N7: اتصال | O7: زغبي | P7: حماية | Q7: فحم | R7: آزوريت | S7: ابتزاز | T7: إخراج
A8: أجر | B8: أداة | C8: أرضية | D8: تغيير | E8: أخلاق | F8: احتباس | G8: أحب | H8: اختراق | I8: أحفاد | J8: احتجاز | K8: هدية | L8: بائع | M8: أخوة | N8: إتقان | O8: نباتية | P8: نقية | Q8: ماء | R8: استخراج | S8: اتهام | T8: أخير
A9: إجماع | B9: أرّخ | C9: استقلال | D9: تفاعل | E9: إدراك | F9: احترار | G9: احترام | H9: أخلاقيات | I9: أدغال | J9: احتلال | K9: وليمة | L9: بحار | M9: إدارة | N9: أتلف | O9: إثمار | P9: إتقان | Q9: متجددة | R9: إسفلت | S9: أثر | T9: إدارة
A10: احترام | B10: أردواز | C10: استوائي | D10: تقاليد | E10: إرادة | F10: احتراق | G10: احتفال | H10: إرادة | I10: أرز | J10: إدانة | K10: تجمع | L10: بديل | M10: أدب | N10: اتهام | O10: أرض | P10: أثر | Q10: مشعة | R10: إسمنت | S10: احتجاز | T10: أدب
A11: احتفل | B11: أرشيف | C11: أقاليم | D11: تكافل | E11: إرادي | F11: احترز | G11: احتفل | H11: ارتفاع | I11: أرض | J11: أرخبيل | K11: فرح | L11: بستاني | M11: أريكة | N11: أثّر | O11: إزهار | P11: اجتماعي | Q11: مفاعل | R11: أكسدة | S11: احتيال | T11: استراحة
A12: إحسان | B12: أرض | C12: إقليم | D12: ثقافة | E12: أزل | F12: احتمال | G12: أدبي | H12: إرث | I12: أرنب | J12: استسلام | K12: زينة | L12: بناء | M12: استراحة | N12: إجراء | O12: استدامة | P12: اجتماعية | Q12: نفط | R12: أكسيد | S12: اختطاف | T12: استعارة
A13: اختيار | B13: إزميل | C13: بحر | D13: سلوك | E13: أزلي | F13: احتياط | G13: إذاعة | H13: أرشد | I13: إسطبل | J13: استغاثة | K13: فلكلور | L13: بهلوان | M13: استرخاء | N13: احترام | O13: استصلاح | P13: أجواء | Q13: نووية | R13: ألمنيوم | S13: إخفاء | T13: استعراض
A14: إخلاص | B14: استخرج | C14: تلوث | D14: طبقة | E14: استحالة | F14: اختبار | G14: إرث | H14: استراتيجية | I14: أسطورة | J14: استيلاء | K14: ضيافة | L14: بواب | M14: استضافة | N14: احترم | O14: اصفرار | P14: احترار | Q14: رياح | R14: ألومنيوم | S14: أداة | T14: استقبال
... A56: تسامح | B56: جدار | C56: صدع | D56: مساواة | E56: تعدد | F56: انقطاع | G56: بارع | H56: تغلب | I56: جحر | J56: تثبيت | K56: تبخير | L56: سائق | M56: ترحيب | N56: انتقاص | O56: حراثة | P56: بقاء | Q56: بروبان | R56: جير | S56: مذنب | T56: بياني
A57: تسبيح | B57: جدارية | C57: صينية | D57: عدالة | E57: تعقل | F57: انقلاب | G57: بث | H57: تفانٍ | I57: جد | J57: تجارة | K57: مباركة | L57: سباك | M57: ترفيه | N57: انتقائي | O57: حراجة | P57: بقايا | Q57: بطارية | R57: جيولوجيا | S57: مسدس | T57: تأثير | V57: عيد
A58: تشهد | B58: جرانيت | C58: عاصمة | D58: عزل | E58: تعميم | F58: انهيار | G58: بدأ | H58: تقدم | I58: جدب | J58: تجريف | K58: دعاء | L58: سريري | M58: تسامح | N58: انحراف | O58: حش | P58: بقية | Q58: بنزين | R58: حاد | S58: معالج | T58: تباين | V58: احتفال
A59: تعصب | B59: جرة | C59: عالم | D59: تنميط | E59: تغير | F59: اهتزاز | G59: بداية | H59: تكتيك | I59: جدة | J59: تحرك | K59: شكر | L59: سفير | M59: تضامن | N59: انحلال | O59: حشرة | P59: بكتيريا | Q59: آلة | R59: حجر | S59: معتدي | T59: تجربة | V59: تقليد
A60: تفانٍ | B60: جزيرة | C60: علم | D60: وصمة | E60: تفرد | F60: بحث | G60: بدلة | H60: تكريم | I60: جدول | J60: تحرير | K60: امتنان | L60: سكرتير | M60: تعاطف | N60: إنساني | O60: حصاد | P60: بلاستيك | Q60: تخزين | R60: حديد | S60: منبه | T60: تجريد | V60: عادة
A61: تفسير | B61: جسر | C61: عملة | D61: حراك | E61: تفكر | F61: بحيرة | G61: براعة | H61: تماسك | I61: جدي | J61: تدفق | K61: عرف | L61: سمسار | M61: تعاون | N61: إنصاف | O61: حظيرة | P61: بلوتونيوم | Q61: تربين | R61: حرير | S61: مهرب | T61: تجريدي | V61: موسم
A62: تقليد | B62: جمع | C62: فيض | D62: ترقي | E62: تفكيكية | F62: بدانة | G62: برافو | H62: تميز | I62: جراد | J62: ترسانة | K62: موروث | L62: شاعر | M62: تعزية | N62: انفتاح | O62: حفظ | P62: بنية | Q62: تسرب | R62: حصاة | S62: نشل | T62: تحرير | V62: هدية
A63: تقوى | B63: جنائزي | C63: فيضان | D63: فقر | E63: تقييم | F63: براعة | G63: برز | H63: تهديد | I63: جرار | J63: تسلح | K63: أصالة | L63: شحاذ | M63: تفانٍ | N63: انفصال | O63: حلم | P63: بيولوجي | Q63: تعدين | R63: حصى | S63: هارب | T63: تدريس | V63: وليمة
A64: تقي | B64: جوهرة | C64: قطب | D64: ثروة | E64: تناقض | F64: برد | G64: برنامج | H64: توازن | I64: جرة | J64: تسليح | K64: هوية | L64: شرطي | M64: تقدير | N64: انقطاع | O64: حموضة | P64: بيئي | Q64: تنمية | R64: خام | S64: هجوم | T64: تذكرة | V64: تجمع
A65: تكبير | B65: جير | C65: قناة | D65: بطالة | E65: تناهي | F65: برق | G65: بروز | H65: ثابت | I65: جزر | J65: تفاوض | K65: رمزية | L65: صانع | M65: تقليد | N65: إهانة | O65: خبير | P65: بيئية | Q65: تيار | R65: خزان | S65: أمن | T65: تذهيب | V65: فرح
A66: تلا | B66: جيولوجيا | C66: كثيب | D66: تعليم | E66: تنوير | F66: بركان | G66: بريق | H66: ثابر | I66: جفاف | J66: تمرد | K66: ذكرى | L66: صائغ | M66: تقييم | N66: اهتمام | O66: دبال | P66: تأثير | Q66: حديد | R66: خزف | S66: انحراف | T66: تراث | V66: زينة
A67: تلاوة | B67: حبر | C67: كيب | D67: تفكك | E67: تنويرية | F67: بطانية | G67: بطل | H67: ثبات | I67: جمعية | J67: تيار | K67: مناسبة | L67: صحفي | M67: تكافل | N67: إهمال | O67: دراسة | P67: تأطير | Q67: خام | R67: خشب | S67: إنذار | T67: تركيز | V67: زي تقليدي
A68: تلميذ | B68: حجر | C68: لغة | D68: تماسك | E68: تواصل | F68: بؤس | G68: بهرج | H68: ثقة | I68: جنازة | J68: ثروة | K68: يوبيل | L68: صراف | M68: تكييف | N68: إيمان | O68: دفيئة | P68: تآكل | Q68: خزان | R68: خيزران | S68: إنكار | T68: تصفيق | V68: موسيقى شعبية
... A88: حالة | B88: ختم | C88: ينبوع | D88: دولة | E88: حيوان | F88: تسونامي | G88: تكريم | H88: حرر | I88: حمامة | J88: حرك | K88: عبرة | L88: فندقي | M88: حجز | N88: تحليل | O88: صدأ | P88: تراكم | Q88: معدن | R88: زئبق | S88: تقرير | T88: جاد | V88: نشيد
A89: حب | B89: خدش | D89: مواطنة | E89: حيوي | F89: تشنج | G89: تكوين | H89: حرك | I89: حمص | J89: حزام | K89: وصية | L89: فني | M89: حديث | N89: تحمل | O89: صلصال | P89: تربة | Q89: منجم | R89: زينون | S89: تناقض | T89: جانب | V89: أضواء
A90: حج | B90: خراب | D90: حقوق | E90: خاص | F90: تصدع | G90: تمتع | H90: حزم | I90: حمل | J90: حساب | K90: إرث | L90: فيزيائي | M90: حديقة | N90: تخلي | O90: صنف | P90: ترسب | Q90: مهنة | R90: سبك | S90: تنظيم | T90: جائزة | V90: فانوس
A91: حجاب | B91: خزان | D91: واجبات | E91: خالد | F91: تضارب | G91: تمجيد | H91: حصار | I91: خبرة | J91: حصار | K91: جيل | L91: فيلسوف | M91: حريرة | N91: تخويف | O91: صومعة | P91: ترشيد | Q91: موارد | R91: سبيكة | S91: تنمر | T91: جدارية | V91: شموع
A92: حديث | B92: خزف | D92: رأسمالية | E92: خصوصية | F92: تطهير | G92: تواضع | H92: حصن | I92: ختان | J92: حصن | K92: أجيال | L92: قابلة | M92: حساب | N92: تدقيق | O92: طفيلي | P92: تركيب | Q92: مولد | R92: سترين | S92: تهديد | T92: جرأة | V92: مأدبة
A93: حر | B93: خشب | D93: اشتراكية | E93: خلود | F93: تعرية | G93: توّج | H93: حفز | I93: خروف | J93: حكم | K93: سلف | L93: قاضٍ | M93: حفاوة | N93: تدهور | O93: طمي | P93: ترميم | Q93: ناقلة | R93: سلسلة | S93: تهريب | T93: جرافيتي | V93: طعام
A94: حرام | B94: خندق | D94: طبقية | E94: خير | F94: تعطل | G94: توضيح | H94: حق | I94: خصوبة | J94: حلقة | K94: خلف | L94: قائد | M94: حقيبة | N94: ترادف | O94: عازقة | P94: تسميد | Q94: نقص | R94: سماد | S94: تواطؤ | T94: جسد | V94: حلوى
A95: حرق | B95: دبال | D95: برجوازية | E95: دائم | F95: تعقيد | G95: توقيع | H95: حماس | I95: خصومة | J95: حمولة | K95: جد | L95: قبطان | M95: حلوى | N95: ترويض | O95: عرض | P95: تصحر | Q95: نواة | R95: سنفرة | S95: توقيف | T95: جسّد | V95: كعك
A96: حرم | B96: دبوس | D96: عمال | E96: دلالة | F96: تعقيم | G96: تيار | H96: حمل | I96: خضار | J96: حوت | K96: جدة | L96: قبعجية | M96: حلويات | N96: تزوير | O96: عزيق | P96: تصريف | Q96: وقود | R96: سيريوم | S96: جاسوس | T96: جسدي | V96: شاي
A97: حساب | B97: دراسة | D97: نقابة | E97: دليل | F97: تعويض | G97: ثروة | H97: حمى | I97: خضروات | J97: خريطة | K97: كرنفال | L97: قدرة | M97: حمام | N97: تسامح | O97: عصارة | P97: تطهير | Q97: أمبير | R97: سيزيوم | S97: جثة | T97: جمال | V97: قهوة
A98: حسنة | B98: درج | D98: احتجاج | E98: ديالكتيك | F98: تغيير | G98: ثقة | H98: حيوية | I98: دار | J98: خسارة | K98: موكب | L98: قطّاع | M98: حماية | N98: تسلية | O98: عضوية | P98: تطور | Q98: امتلاء | R98: سيليكا | S98: جريمة | T98: جمالية | V98: ضيوف
A99: حكم | B99: درس | D99: ثورة | E99: ذات | F99: تفتيش | G99: ثلاثية | H99: خط | I99: دجاجة | J99: خطاف | K99: عروس | L99: قنصل | M99: حنان | N99: تسمية | O99: علاج | P99: تعليم | Q99: إمدادات | R99: شلال | S99: جنحة | T99: جمهور | V99: أقارب
A100: حكيم | B100: درع | D100: تمرد | E100: ذاتية | F100: تقلب | G100: ثناء | H100: خطر | I100: درب | J100: خطر | K100: عريس | L100: قيّم | M100: خادم | N100: تشتت | O100: علف | P100: تغليف | Q100: أنابيب | R100: شمشار | S100: جهاز | T100: جميل | V100: جيران
...

Sheet M5
A1: ALKAMO — M5 (arabe) ARABE
A3: N° | B3: THÈME | C3: MOTS
A4: 1 | B4: العقل والتفكير | C4: =M5_mots!A2 -> 215
A5: 2 | B5: علم النفس | C5: =M5_mots!B2 -> 151
A6: 3 | B6: المفاهيم والأفكار | C6: =M5_mots!C2 -> 413
A7: 4 | B7: المشاعر والعواطف | C7: =M5_mots!D2 -> 394
A8: 5 | B8: علم الفلك | C8: =M5_mots!E2 -> 255
A9: 6 | B9: الجيولوجيا وعلوم الأرض | C9: =M5_mots!F2 -> 298
A10: 7 | B10: العلوم والمعرفة | C10: =M5_mots!G2 -> 358
A11: 8 | B11: السلام والسياسة | C11: =M5_mots!H2 -> 460
A12: 9 | B12: العجائب والمعالم | C12: =M5_mots!I2 -> 357
A13: 10 | B13: الإنسانية | C13: =M5_mots!J2 -> 321
A14: 11 | B14: التربية والبيداغوجيا | C14: =M5_mots!K2 -> 375
A15: 12 | B15: الصناعات | C15: =M5_mots!L2 -> 336
A16: 13 | B16: النقل القديم والبدائي | C16: =M5_mots!M2 -> 106
A17: 14 | B17: الخوف والحب | C17: =M5_mots!N2 -> 155
A18: 15 | B18: الفيزياء والقوام | C18: =M5_mots!O2 -> 400
A19: 16 | B19: الفكر والرأي | C19: =M5_mots!P2 -> 461
A20: 17 | B20: المعمار والتصميم | C20: =M5_mots!Q2 -> 426
A21: 18 | B21: الأرض والكون | C21: =M5_mots!R2 -> 387
A22: 19 | B22: الشعر والبلاغة | C22: =M5_mots!S2 -> 362
A23: 20 | B23: الدبلوماسية والعلاقات الدولية | C23: =M5_mots!T2 -> 495
A24: 21 | B24: قواعد اللغة | C24: =M5_mots!U2 -> 243
A25: 22 | B25: الاتصال ووسائل الإعلام | C25: =M5_mots!V2 -> 382
A26: 23 | B26: الفروسية وحياة البادية | C26: =M5_mots!W2 -> 133
A27: 24 | B27: الخط العربي والزخرفة | C27: =M5_mots!X2 -> 120
A28: 25 | B28: الفنون | C28: =M5_mots!Y2 -> 262
A29: TOTAL | C29: =SUM(C4:C28) -> 7865

Sheet M5_mots
A1: العقل والتفكير | B1: علم النفس | C1: المفاهيم والأفكار | D1: المشاعر والعواطف | E1: علم الفلك | F1: الجيولوجيا وعلوم الأرض | G1: العلوم والمعرفة | H1: السلام والسياسة | I1: العجائب والمعالم | J1: الإنسانية | K1: التربية والبيداغوجيا | L1: الصناعات | M1: النقل القديم والبدائي | N1: الخوف والحب | O1: الفيزياء والقوام | P1: الفكر والرأي | Q1: المعمار والتصميم | R1: الأرض والكون | S1: الشعر والبلاغة | T1: الدبلوماسية والعلاقات الدولية | U1: قواعد اللغة | V1: الاتصال ووسائل الإعلام | W1: الفروسية وحياة البادية | X1: الخط العربي والزخرفة | Y1: الفنون
A2: =COUNTA(A3:A5000) -> 215 | B2: =COUNTA(B3:B5000) -> 151 | C2: =COUNTA(C3:C5000) -> 413 | D2: =COUNTA(D3:D5000) -> 394 | E2: =COUNTA(E3:E5000) -> 255 | F2: =COUNTA(F3:F5000) -> 298 | G2: =COUNTA(G3:G5000) -> 358 | H2: =COUNTA(H3:H5000) -> 460 | ... Y2: =COUNTA(Y3:Y5000) -> 262
A3: إقناع | B3: نفس | C3: ابتكار | D3: عيد | E3: أثر | F3: أرضية | G3: ابتدائي | H3: سياسي | I3: أهرامات | J3: ابتكر | K3: أب | L3: ابتكر | M3: سفر | N3: أب | O3: جميلة | P3: فكري | Q3: معماري | R3: استواء | S3: ابتكار | T3: اتحاد | U3: أبجدية | V3: إعلام | W3: أخوة | X3: خط | Y3: ابتكار | AB3: سياسي
A4: رأي | B4: شخصية | C4: ابتكر | D4: احتفال | E4: أحفورة | F4: أثر | G4: آثار | H4: اتصال | I4: كولوسيوم | J4: اتحاد | K4: ابتدائي | L4: إبداع | M4: اتجاه | N4: ابتسامة | O4: شائب | P4: منطقي | Q4: ابتكار | R4: أوزون | S4: إبداع | T4: اتصال | U4: اتفاق | V4: أبكم | W4: إرادة | X4: قلم | Y4: إبداع | AB4: اتصال
A5: قول | B5: سلوك | C5: إبداع | D5: تقليد | E5: اختلاف | F5: أحافير | G5: اجتماع | H5: اتفاق | I5: منارة | J5: اتصال | K5: ابتكار | L5: إتقان | M5: استراحة | N5: ابن | O5: شائبة | P5: ابتذال | Q5: ابتكر | R5: جوي | S5: أبواب | T5: اتفاق | U5: أثرى | V5: أبلغ | W5: استدارة | X5: حبر | Y5: إخراج | AB5: اتفاق
A6: حاد | B6: وعي | C6: اتساق | D6: عادة | E6: اختيار | F6: أحفورة | G6: اجتماعية | H6: اتفاقية | I6: قصر | J6: اتفاق | K6: ابتكر | L6: أثر | M6: استكشاف | N6: ابنة | O6: إبهام | P6: ابتكار | Q6: إبداع | R6: اتساع | S6: أحجية | T6: اتفاقية | U6: أجوف | V6: اتصال | W6: استقرار | X6: نسخ | Y6: أخير | AB6: اتفاقية
A7: دقة | B7: لاوعي | C7: اتفاق | D7: موسم | E7: ارتفاع | F7: أحياء | G7: أحب | H7: اتفق | I7: معبد | J7: إتقان | K7: أبوي | L7: أجيال | M7: إضاءة | N7: احترام | O7: أبيض | P7: إبداع | Q7: آبنوس | R7: أجمة | S7: أحداث | T7: اتفق | U7: أحجية | V7: اتصل | W7: إغاثة | X7: ثلث | Y7: أدب | AB7: اتفق
A8: ذكيا | B8: دافع | C8: آثار | D8: هدية | E8: أرض | F8: إخلاء | G8: احتمال | H8: اتهم | I8: متحف | J8: احترام | K8: إتقان | L8: احتراف | M8: أفق | N8: أخ | O8: اتجاه | P8: اتجاه | Q8: أثاث | R8: احتباس | S8: إحساس | T8: اتهم | U8: أداة | V8: اتهام | W8: إقدام | X8: ديواني | Y8: استمع | AB8: اتهم
A9: غريب | B9: قلق | C9: أثبت | D9: وليمة | E9: أرضي | F9: أداة | G9: إحصاء | H9: اجتماع | I9: أثر | J9: إحسان | K9: إثراء | L9: اختراع | M9: اكتشاف | N9: أخت | O9: أثر | P9: اتفاق | Q9: اختراع | R9: احترار | S9: إحيائي | T9: اجتماع | U9: ارتباك | V9: أثبت | W9: أمان | X9: كوفي | Y9: أسطورة | AB9: اجتماع
A10: فكرة | B10: اكتئاب | C10: أثر | D10: تجمع | E10: استقرار | F10: ارتجاف | G10: إحصائي | H10: إجماع | I10: عجيبة | J10: أخ | K10: أثرى | L10: يدوية | M10: أمتعة | N10: اختيار | O10: احتكاك | P10: أثر | Q10: اخترع | R10: إحداثيات | S10: أدب | T10: إجماع | U10: استثناء | V10: أثر | W10: أمانة | X10: زخرفة | Y10: أسلوب | AB10: إجماع
A11: فهم | B11: سعادة | C11: إجابة | D11: فرح | E11: أسود | F11: ارتفاع | G11: أحياء | H11: احتفال | I11: رمز | J11: اختار | K11: إجازة | L11: أداة | M11: انطلاق | N11: إخلاص | O11: إحساس | P11: أثّر | Q11: ارتفاع | R11: إحداثية | S11: أدبي | T11: احتفال | U11: استخدام | V11: اجتماعي | W11: امتطاء | X11: نقش | Y11: إضاءة | AB11: احتفال
A12: مخطئ | B12: ذاكرة | C12: اجتماعي | D12: زينة | E12: إشارة | F12: أردواز | G12: أحيائي | H12: اختار | I12: معلم | J12: اختلاف | K12: احترام | L12: أدار | M12: بطء | N12: إرادة | O12: أخضر | P12: اجترار | Q12: إرث | R12: أحياء | S12: أديب | T12: احتلال | U12: استدلال | V12: أجواء | W12: أمن | X12: زخارف | Y12: إطار | AB12: اختار
A13: مشتت | B13: إدراك | C13: أجزاء | D13: فلكلور | E13: إشعاع | F13: أرض | G13: اختبار | H13: اختيار | I13: وجهة | J13: اختيار | K13: احتياج | L13: إدارة | M13: بغل | N13: أسرة | O13: أخلاق | P13: اجتماعي | Q13: أرخبيل | R13: أخدود | S13: ارتجال | T13: اختار | U13: استعارة | V13: إحاطة | W13: انسجام | X13: لوحة | Y13: إعجاب | AB13: اختيار
A14: مهم | B14: عاطفة | C14: إجماع | D14: ضيافة | E14: أصل | F14: أرضي | G14: اختراع | H14: أخلاقيات | I14: سياحة | J14: إخلاص | K14: أخ | L14: أدوات | M14: بغلة | N14: أسف | O14: إرادة | P14: أجّل | Q14: أردواز | R14: ارتجاف | S14: أرجوزة | T14: اختيار | U14: أسلوب | V14: احتج | W14: إنصاف | X14: خطاط | Y14: أغنية | AB14: أخلاقيات
... A108: دقيق | B108: انبساطي | C108: تساؤل | D108: إحساس | E108: شرط | F108: خرائط | G108: تقييم | H108: تعاون | I108: دهشة | J108: حضارة | K108: توضيح | L108: خشب | M108: مسار | N108: عهد | O108: حالة | P108: تخيل | Q108: جدارية | R108: جنوبي | S108: حروف | T108: تحفظ | U108: صامت | V108: ثرثار | W108: لجام | X108: فنية | Y108: زخرفة | AB108: تطبيع
A109: دقيقة | B109: توحد | C109: تشابه | D109: احمرار | E109: شروق | F109: خريطة | G109: تكلم | H109: تعددية | I109: كرنفال | J109: حق | K109: ثانوي | L109: خصب | N109: عودة | O109: حجم | P109: تخيلات | Q109: جذع | R109: جو | S109: حسرة | T109: تحكيم | U109: صحح | V109: ثرثر | W109: مباغتة | X109: دلالة | Y109: زخرفي | AB109: تعاون
A110: دليل | B110: إدمان | C110: تصور | D110: أدار | E110: شعار | F110: خطر | G110: تكنولوجيا | H110: تعليم | I110: معاصر | J110: حقوق | K110: ثانوية | L110: خفيف | N110: عين | O110: حرارة | P110: تراجع | Q110: جرانيت | R110: جوفي | S110: حشو | T110: تحمل | U110: صحيح | V110: ثرثرة | W110: مثابرة | X110: مضمون | Y110: زي | AB110: تعددية
A111: ذات | B111: انتكاسة | C111: تصورات | D111: ارتباك | E111: شعب | F111: خفاف | G111: تكوين | H111: تغيير | I111: رائع | J111: حقيقة | K111: ثقافة | L111: خمّر | N111: غرام | O111: حركة | P111: تركيز | Q111: جرثومة | R111: جوية | S111: حضارة | T111: تداول | U111: صرّف | V111: ثقافة | W111: محبة | X111: مظهر | Y111: ستار | AB111: تعليم
A112: ذاكرة | B112: شفاء | C112: تطور | D112: ارتجف | E112: شمال | F112: خفيف | G112: تلخيص | H112: تفاهم | I112: إعجاب | J112: حكاية | K112: ثقافي | L112: خميرة | N112: غضب | O112: حزم | P112: تسامح | Q112: جرس | R112: جيولوجيا | S112: حفظ | T112: تزوير | U112: صفة | V112: جدول | W112: مروءة | X112: هيئة | Y112: سحر | AB112: تغيير
A113: ذهن | B113: تعافي | C113: تطوير | D113: ارتياح | E113: شمس | F113: خليج | G113: تلميذ | H113: تفاوض | I113: أعجب | J113: حكمة | K113: ثقة | L113: دباغة | N113: غفران | O113: حساس | P113: تشاور | Q113: جسر | R113: حار | S113: حقيقة | T113: تشابه | U113: صوت | V113: جريدة | W113: مشورة | X113: تكوين | Y113: سلم | AB113: تفاهم
A114: رغبة | B114: مرونة | C114: تعارض | D114: أزعج | E114: شمسي | F114: دائري | G114: تمدرس | H114: تقارب | I114: عبادة | J114: حلم | K114: ثقف | L114: دخان | N114: غيرة | O114: حضور | P114: تشاؤم | Q114: جص | R114: حارة | S114: حكايات | T114: تصديق | U114: صورة | V114: جمع | W114: مضمار | X114: تركيب | Y114: سماعة | AB114: تفاوض
A115: رمزي | B115: صمود | C115: تعدد | D115: أزمة | E115: شهاب | F115: دخان | G115: تمرين | H115: تقدم | I115: ممتع | J115: حليف | K115: ثواب | L115: دراسة | N115: فرار | O115: حطام | P115: تشتت | Q115: جمالية | R115: حجب | S115: حكاية | T115: تصرف | U115: صياغة | V115: جمهور | W115: معركة | X115: عناصر | Y115: سهولة | AB115: تقارب
A116: روح | B116: تحمل | C116: تعددية | D116: استسلم | E116: صاروخ | F116: دراسة | G116: تمييز | H116: تقشف | I116: متعة | J116: حماية | K116: جامعي | L116: درفلة | N116: فراق | O116: حقيقي | P116: تصريح | Q116: جمجمة | R116: حديقة | S116: حكم | T116: تصريح | U116: صيغة | V116: جواب | W116: مهارة | X116: مكونات | Y116: سيرك | AB116: تقدم
A117: رؤية | B117: يأس | C117: تعريف | D117: استفز | E117: صيف | F117: درس | G117: تنجيم | H117: تكتل | I117: بهجة | J117: حنان | K117: جدارة | L117: دقة | N117: فرح | O117: حمى | P117: تصنيف | Q117: جمع | R117: حراث | S117: حكمة | T117: تصعيد | U117: ضد | V117: حبر | W117: مهماز | X117: تفاصيل | Y117: سيناريو | AB117: تقشف
A118: سرمدي | B118: أمل | C118: تعريفات | D118: استقرار | E118: ضباب | F118: دلتا | G118: توازن | H118: تماسك | I118: مدرج | J118: حوار | K118: جدول | L118: دقيق | N118: فزع | O118: حي | P118: تصور | Q118: جوهرة | R118: حرارة | S118: حل | T118: تصويت | U118: ضمة | V118: حجة | W118: مؤازرة | X118: دقائق | Y118: سينما | AB118: تكتل
A119: سوء | B119: رضا | C119: تغيير | D119: استياء | E119: ضعيف | F119: دهر | G119: تواضع | H119: تنازل | I119: قديم | J119: حياة | K119: جزاء | L119: دكان | N119: قرابة | O119: حياة | P119: تصويت | Q119: جير | R119: حرث | S119: حماسة | T119: تطبيع | U119: ضمني | V119: حدث | W119: ميدان | X119: ملامح | Y119: شاشة | AB119: تماسك
A120: سؤال | B120: قناعة | C120: تفسير | D120: أسر | E120: ضغط | F120: ذهب | G120: توضيح | H120: تنافس | I120: عتيق | J120: خدمة | K120: جماعي | L120: دهان | N120: قرب | O120: حيود | P120: تطرف | Q120: حاجز | R120: حرك | S120: حنين | T120: تعاون | U120: ضمير | V120: حديث | W120: ناقة | X120: سمات | Y120: شاعر | AB120: تنازل
... A122: شك | B122: إرادة | C122: تفكير | D122: آسف | E122: طاقة | F122: رجفة | G122: ثانوية | H122: تنمية | I122: قناة | J122: خطاب | K122: جوقة | L122: ذكي | N122: قلب | O122: حيوية | P122: تعبئة | Q122: حامل | R122: حصاد | S122: حوارية | T122: تفاهم | U122: طريقة | V122: حذّر | W122: نجمة | X122: مميزات | Y122: شعر | AB122: تنفيذي
A123: صحيح | B123: عزيمة | C123: تقدم | D123: أسى | E123: طائرة | F123: رحلة | G123: ثقافة | H123: توقيع | I123: رواق | J123: خلود | K123: حافز | L123: رأسمال | N123: قلق | O123: خامل | P123: تعدد | Q123: حبة | R123: حضيض | S123: خاتمة | T123: تفويض | U123: عامي | V123: حرر | W123: نخوة | Y123: شكل | AB123: تنمية
A124: صلة | B124: تقدير | C124: تقنية | D124: أشفق | E124: طور | F124: رخام | G124: جامعة | H124: تيار | I124: معماري | J124: خير | K124: حدس | L124: رافعة | N124: قوة | O124: خد | P124: تعددية | Q124: حبر | R124: حفر | S124: خاطرة | T124: تقارب | U124: عامية | V124: حرية | W124: نخيل | Y124: شيء | AB124: توقيع
A125: صواب | B125: بصيرة | C125: تماسك | D125: اشمئزاز | E125: طيف | F125: ردم | G125: جامعي | H125: ثقة | I125: عمارة | J125: درس | K125: حذر | L125: رحى | N125: كذب | O125: خسارة | P125: تعصب | Q125: حبل | R125: حفرة | S125: خرافة | T125: تقدم | U125: عبارة | V125: حساب | W125: نصر | Y125: صالة | AB125: تيار
A126: طبيعة | B126: حدس | C126: تمييز | D126: اضطراب | E126: ظاهرة | F126: رسوب | G126: جاهل | H126: ثنائية | I126: أرشيف | J126: درّس | K126: حرم | L126: رذاذ | N126: كره | O126: خشن | P126: تعليق | Q126: حجر | R126: حفظ | S126: خط | T126: تقشف | U126: عبّر | V126: حصيلة | W126: نفوذ | Y126: صوت | AB126: ثقة
A127: ظاهر | B127: لاشعور | C127: تناقض | D127: إعجاب | E127: ظل | F127: رسوبي | G127: جدلية | H127: ثورة | I127: حماس | J127: دعم | K127: حرية | L127: رقابة | N127: كلمة | O127: خشونة | P127: تعليم | Q127: حجم | R127: حقل | S127: خطابة | T127: تكتل | U127: عدد | V127: حظر | W127: هجوم | Y127: صورة | AB127: ثنائية
A128: ظن | B128: عقل | C128: تنظيم | D128: أعجب | E128: ظلام | F128: رسوبيات | G128: جغرافيا | H128: جانب | I128: أردواز | J128: دماغ | K128: حساب | L128: رماد | N128: لطف | O128: خلية | P128: تعمق | Q128: حداثة | R128: حلزون | S128: خطبة | T128: تماسك | U128: عربية | V128: حق | W128: هزيمة | Y128: ضجيج | AB128: ثورة
A129: عبرة | B129: روح | C129: تنوع | D129: أعصب | E129: عالم | F129: رصاص | G129: جمع | H129: جدير | I129: فن | J129: دولة | K129: حصيلة | L129: رواسب | N129: لق | O129: دالة | P129: تعيين | Q129: حديث | R129: حلزوني | S129: خمريات | T129: تمثيل | U129: عروض | V129: حقيقة | W129: هيبة | Y129: طباعة | AB129: جانب
A130: عبقري | B130: نفسية | C130: توازن | D130: ألم | E130: عبور | F130: ركاز | G130: جنون | H130: جريدة | I130: حرفة | J130: دين | K130: حضانة | L130: ريحي | N130: لقاء | O130: دائرة | P130: تغلغل | Q130: حديد | R130: حيوان | S130: دراسة | T130: تنازل | U130: عطف | V130: حل | W130: واحة | Y130: طبع | AB130: جدير
A131: عبقرية | B131: انفصام | C131: توضيح | D131: آلم | E131: عدسة | F131: رماد | G131: جهل | H131: جلب | I131: فنان | J131: ذاكرة | K131: حفز | L131: ريش | N131: محبة | O131: دراسة | P131: تفسير | Q131: حديقة | R131: حيوانات | S131: دلالات | T131: تنافس | U131: علامة | V131: حملة | W131: وثب | Y131: طبلة | AB131: جريدة
A132: عدم | B132: هذيان | C132: توقف | D132: آلية | E132: عطارد | F132: رملي | G132: جواب | H132: جلسة | I132: فني | J132: ذكرى | K132: حفظ | L132: زبدة | N132: مساعدة | O132: درجة | P132: تفكير | Q132: حرارة | R132: حيوية | S132: دوريات | T132: تنفيذي | U132: علم | V132: حياد | W132: ود | Y132: طبيعة | AB132: جلب
A133: عزم | B133: جنون | C133: ثقافي | D133: أمل | E133: عقدة | F133: رواسب | G133: جيولوجيا | H133: جمع | I133: ورشة | J133: رابطة | K133: حكاية | L133: زبون | N133: مسامحة | O133: درس | P133: تفلسف | Q133: حراسة | R133: خارجية | S133: دورية | T133: تهدئة | U133: عنصر | V133: خادم | W133: وفاء | Y133: طموح | AB133: جلسة
A134: عقل | B134: عبقرية | C134: ثنائية | D134: انتصر | E134: علم | F134: زبرجد | G134: حدس | H134: جمعية | I134: جذب | J134: راحة | K134: حل | L134: زجاج | N134: مساندة | O134: درع | P134: تفنيد | Q134: حرشفة | R134: خريطة | S134: ديار | T134: توتر | U134: عيّن | V134: خاص | W134: وقار | Y134: طين | AB134: جمع
...

Sheet RÉCAP GLOBAL
J1: Nb mots | K1: Nb thèmes | L1: Maquette
J2: ='M1'!C24 -> 6418 | K2: 20 | L2: M1
J3: ='M2'!C24 -> 5743 | K3: 20 | L3: M2
J4: ='M3'!C24 -> 5268 | K4: 20 | L4: M3
J5: ='M4'!C24 -> 5645 | K5: 20 | L5: M4
J6: ='M5'!C29 -> 7865 | K6: 25 | L6: M5
J7: =SUM(J2:J6) -> 30939 | K7: =SUM(K2:K6) -> 105 | L7: TOTAL

Sheet LÉGENDE
A1: Légende — ALKAMO Dictionnaire Arabe (réceptacle)
A3: • Structure calquée sur ALKAMO_dictionnaire.xlsx (français) : un onglet Mx (thèmes + comptage) et un onglet Mx_mots (mots par thème en colonnes) pour chaque maquette.
A4: • 105 thèmes au total (4×20 + 25), en excluant les 5 cases 'mots libres' de chaque maquette M1-M4 (pas de nom de thème, mot du dictionnaire accepté sans vérification).
